<?xml version="1.0"?>
<robot name="sj705" xmlns:xacro="http://www.ros.org/wiki/xacro">

<!-- Import Rviz colors -->
<xacro:include filename="$(find sj705_gazebo)/urdf/materials.xacro" />
  
<!-- Import all Gazebo-customization elements, including  colors -->
<xacro:include filename="$(find sj705_gazebo)/urdf/sj705.gazebo" />

 <!-- Constants for robot dimensions -->
  <xacro:property name="PI" value="3.1415926535897931"/>
  <xacro:property name="link1_z" value="0.1985" /> 
  <xacro:property name="link3_z" value="0.31" />
  <xacro:property name="link5_z" value="0.218" />
  <xacro:property name="link7_z" value="0.048" />
  <xacro:property name="mass" value="1" /> 

  <link name="world"/>

  <joint name="fixed" type="fixed">
    <parent link="world"/>
    <child link="base_link"/>
  </joint>


  <link name="base_link">
    <collision>
      <geometry>
        <mesh filename="package://sj705_gazebo/meshes/sj705/base.dae"/> 
      </geometry>
      <origin xyz="0 0 0"/>
    </collision>
    
    <visual>
      <geometry>
        <mesh filename="package://sj705_gazebo/meshes/sj705/base.dae"/> 
      </geometry>
      <material name="grey"/>
      <origin xyz="0 0 0"/>
    </visual>

    <inertial>
      <origin xyz="0 0 0" rpy="0 0 0"/>
      <mass value="${mass}"/>
      <inertia
	  ixx="${mass}" ixy="0.0" ixz="0.0"
	  iyy="${mass}" iyz="0.0"
	  izz="${mass}"/>
    </inertial>
  </link>

  <link name="link1">
    <collision>
     <geometry>
        <mesh filename="package://sj705_gazebo/meshes/sj705/link1.dae"/>       
     </geometry>
     <origin xyz="0 0 0"/>
    </collision>

    <visual>
     <geometry>
        <mesh filename="package://sj705_gazebo/meshes/sj705/link1.dae"/> 
     </geometry>
     <material name="white"/>
     <origin xyz="0 0 0"/>
    </visual>

    <inertial>
     <origin xyz="0 0 0"/>
      <mass value="${mass/2}"/>
      <inertia
	   ixx="${mass/2}" ixy="0.0" ixz="0.0"
	   iyy="${mass/2}" iyz="0.0"
	   izz="${mass/2}"/>
    </inertial>
  </link>

  <joint name="joint1" type="revolute">
   <axis xyz="0 0 1"/>
   <limit effort="1000.0" lower="-3.14" upper="3.14" velocity="0.5"/>
   <parent link="base_link"/>
   <child link="link1"/>
   <origin xyz="0 0 ${link1_z}"/>
  </joint>

  <link name="link2">
    <collision>
      <geometry>
       <mesh filename="package://sj705_gazebo/meshes/sj705/link2.dae"/>
     </geometry>
     <origin rpy="0 0 0"/>
    </collision>

    <visual>
     <geometry>
       <mesh filename="package://sj705_gazebo/meshes/sj705/link2.dae"/>
     </geometry>
     <material name="white"/>
     <origin rpy="0 0 0"/>
    </visual>

    <inertial>
      <origin rpy="0 0 0"/>
      <mass value="${mass/2}"/>
      <inertia
     ixx="${mass/2}" ixy="0.0" ixz="0.0"
	   iyy="${mass/2}" iyz="0.0"
	   izz="${mass/2}"/>
    </inertial>
  </link>

  <joint name="joint2" type="revolute">
   <axis xyz="0 1 0"/>
   <limit effort="1000.0" lower="-3.14" upper="3.14" velocity="0.5"/>
   <parent link="link1"/>
   <child link="link2"/>
   <origin xyz="0 0 0"/>
  </joint>

  <link name="link3">
    <collision>
     <geometry>
         <mesh filename="package://sj705_gazebo/meshes/sj705/link3.dae"/>
     </geometry>
     <origin xyz="0 0 0"/>
    </collision>
   
    <visual>
     <geometry>
       <mesh filename="package://sj705_gazebo/meshes/sj705/link3.dae"/>
     </geometry>
     <origin xyz="0 0 0"/>
    </visual>

    <inertial>
      <origin xyz="0 0 0"/>
      <mass value="${mass/2}"/>
      <inertia
	   ixx="${mass/2}" ixy="0.0" ixz="0.0"
	   iyy="${mass/2}" iyz="0.0"
	   izz="${mass/2}"/>
    </inertial>
  </link>

  <joint name="joint3" type="revolute">
   <axis xyz="0 0 1"/>
   <limit effort="1000.0" lower="-3.14" upper="3.14" velocity="0.5"/>
   <parent link="link2"/>
   <child link="link3"/>
   <origin xyz="0 0 ${link3_z}" rpy="0 0 0"/>
  </joint>

  <link name="link4">
    <collision>
     <geometry>
       <mesh filename="package://sj705_gazebo/meshes/sj705/link4.dae"/>
     </geometry>
     <origin rpy="0 0 0"/>
    </collision>
    
    <visual>
     <geometry>
       <mesh filename="package://sj705_gazebo/meshes/sj705/link4.dae"/>
     </geometry>
     <origin rpy="0 0 0"/>
    </visual>

    <inertial>
      <origin xyz="0 0 0"/>
      <mass value="${mass/2}"/>
      <inertia
	   ixx="${mass/2}" ixy="0.0" ixz="0.0"
	   iyy="${mass/2}" iyz="0.0"
	   izz="${mass/2}"/>
    </inertial>
  </link>

  <joint name="joint4" type="revolute">
   <axis xyz="0 1 0"/>
   <limit effort="1000.0" lower="-3.14" upper="3.14" velocity="0.5"/>
   <parent link="link3"/>
   <child link="link4"/>
   <origin xyz="0 0 0"/>
  </joint>

  <link name="link5">
    <collision>
     <geometry>
       <mesh filename="package://sj705_gazebo/meshes/sj705/link5.dae"/>
     </geometry>
     <origin rpy="0 0 0" xyz="0 0 0"/>
    </collision>

    <visual>
     <geometry>
       <mesh filename="package://sj705_gazebo/meshes/sj705/link5.dae"/>
     </geometry>
     <material name="white"/>
     <origin rpy="0 0 0" xyz="0 0 0"/>
    </visual>

    <inertial>
     <origin rpy="0 0 0" xyz="0 0 0"/>
      <mass value="${mass/2}"/>
      <inertia
	   ixx="${mass/2}" ixy="0.0" ixz="0.0"
	   iyy="${mass/2}" iyz="0.0"
	   izz="${mass/2}"/>
    </inertial>
  </link>

  <joint name="joint5" type="revolute">
   <axis xyz="0 0 1"/>
   <limit effort="1000.0" lower="-3.14" upper="3.14" velocity="0.5"/>
   <parent link="link4"/>
   <child link="link5"/>
   <origin xyz="0 0 ${link5_z}"/>
  </joint>

<link name="link6">
    <collision>
     <geometry>
       <mesh filename="package://sj705_gazebo/meshes/sj705/link6.dae"/>
     </geometry>
     <origin rpy="0 0 0" xyz="0 0 0"/>
    </collision>

    <visual>
     <geometry>
       <mesh filename="package://sj705_gazebo/meshes/sj705/link6.dae"/>
     </geometry>
     <material name="white"/>
     <origin rpy="0 0 0" xyz="0 0 0"/>
    </visual>

    <inertial>
     <origin rpy="0 0 0" xyz="0 0 0"/>
      <mass value="${mass/2}"/>
      <inertia
	   ixx="${mass/2}" ixy="0.0" ixz="0.0"
	   iyy="${mass/2}" iyz="0.0"
	   izz="${mass/2}"/>
    </inertial>
  </link>

  <joint name="joint6" type="revolute">
   <axis xyz="0 1 0"/>
   <limit effort="1000.0" lower="-3.14" upper="3.14" velocity="0.5"/>
   <parent link="link5"/>
   <child link="link6"/>
   <origin xyz="0 0 0"/>
  </joint>

<link name="link7">
    <collision>
     <geometry>
       <mesh filename="package://sj705_gazebo/meshes/sj705/link7.dae"/>
     </geometry>
     <origin rpy="0 0 0" xyz="0 0 0"/>
    </collision>

    <visual>
     <geometry>
       <mesh filename="package://sj705_gazebo/meshes/sj705/link7.dae"/>
     </geometry>
     <material name="white"/>
     <origin rpy="0 0 0" xyz="0 0 0"/>
    </visual>

    <inertial>
     <origin rpy="0 0 0" xyz="0 0 0"/>
      <mass value="${mass/2}"/>
      <inertia
	   ixx="${mass/2}" ixy="0.0" ixz="0.0"
	   iyy="${mass/2}" iyz="0.0"
	   izz="${mass/2}"/>
    </inertial>
  </link>

  <joint name="joint7" type="revolute">
   <axis xyz="0 0 1"/>
   <limit effort="1000.0" lower="-3.14" upper="3.14" velocity="0.5"/>
   <parent link="link6"/>
   <child link="link7"/>
   <origin xyz="0 0 ${link7_z}"/>
  </joint>

  <transmission name="tran1">
    <type>transmission_interface/SimpleTransmission</type>
    <joint name="joint1">
      <hardwareInterface>hardware_interface/EffortJointInterface</hardwareInterface>
    </joint>
    <actuator name="motor1">
      <hardwareInterface>hardware_interface/EffortJointInterface</hardwareInterface>
      <mechanicalReduction>1</mechanicalReduction>
    </actuator>
  </transmission>

  <transmission name="tran2">
    <type>transmission_interface/SimpleTransmission</type>
    <joint name="joint2">
      <hardwareInterface>hardware_interface/EffortJointInterface</hardwareInterface>
    </joint>
    <actuator name="motor2">
      <hardwareInterface>hardware_interface/EffortJointInterface</hardwareInterface>
      <mechanicalReduction>1</mechanicalReduction>
    </actuator>
  </transmission>

    <transmission name="tran3">
    <type>transmission_interface/SimpleTransmission</type>
    <joint name="joint3">
      <hardwareInterface>hardware_interface/EffortJointInterface</hardwareInterface>
    </joint>
    <actuator name="motor3">
      <hardwareInterface>hardware_interface/EffortJointInterface</hardwareInterface>
      <mechanicalReduction>1</mechanicalReduction>
    </actuator>
  </transmission>

  <transmission name="tran4">
    <type>transmission_interface/SimpleTransmission</type>
    <joint name="joint4">
      <hardwareInterface>hardware_interface/EffortJointInterface</hardwareInterface>
    </joint>
    <actuator name="motor4">
      <hardwareInterface>hardware_interface/EffortJointInterface</hardwareInterface>
      <mechanicalReduction>1</mechanicalReduction>
    </actuator>
  </transmission>

  <transmission name="tran5">
    <type>transmission_interface/SimpleTransmission</type>
    <joint name="joint5">
      <hardwareInterface>hardware_interface/EffortJointInterface</hardwareInterface>
    </joint>
    <actuator name="motor5">
      <hardwareInterface>hardware_interface/EffortJointInterface</hardwareInterface>
      <mechanicalReduction>1</mechanicalReduction>
    </actuator>
  </transmission>


  <transmission name="tran6">
    <type>transmission_interface/SimpleTransmission</type>
    <joint name="joint6">
      <hardwareInterface>hardware_interface/EffortJointInterface</hardwareInterface>
    </joint>
    <actuator name="motor6">
      <hardwareInterface>hardware_interface/EffortJointInterface</hardwareInterface>
      <mechanicalReduction>1</mechanicalReduction>
    </actuator>
  </transmission>

  <transmission name="tran7">
    <type>transmission_interface/SimpleTransmission</type>
    <joint name="joint7">
      <hardwareInterface>hardware_interface/EffortJointInterface</hardwareInterface>
    </joint>
    <actuator name="motor7">
      <hardwareInterface>hardware_interface/EffortJointInterface</hardwareInterface>
      <mechanicalReduction>1</mechanicalReduction>
    </actuator>
  </transmission>

</robot>